Workbook

Sheet Расценки
B2: РАСЦЕНКИ НА РАБОТЫ
B3: Сентябрь · прайс по скану · цены за единицу, ₽
B5: Жёлтая заливка — цена или позиция вписаны / исправлены от руки. Розовая — обведено на скане. Серая зачёркнутая — «не входит». В скане нет позиции № 12.
B6: № | C6: Наименование работ | D6: Ед. изм. | E6: Цена, ₽ | F6: Кол-во | G6: Сумма, ₽ | H6: Примечание | I6: Раздел
B7: Полы и стяжка
B8: 1 | C8: Устройство гидроизоляции полов, два слоя | D8: м² | E8: 400 | G8: =IF(OR(F8="",F8=0),0,E8*F8) | I8: Полы и стяжка
B9: 2 | C9: Устройство цементно-песчаной стяжки до 50 мм | D9: м² | E9: 700 | G9: =IF(OR(F9="",F9=0),0,E9*F9) | I9: Полы и стяжка
B10: 3 | C10: Устройство цементно-песчаной стяжки более 50 мм (на каждые 10 мм увеличения толщины) | D10: м² | E10: 150 | G10: =IF(OR(F10="",F10=0),0,E10*F10) | I10: Полы и стяжка
B11: Потолки и монтаж
B12: 4 | C12: Монтаж потолка Грильято | D12: м² | E12: 1000 | G12: =IF(OR(F12="",F12=0),0,E12*F12) | H12: Цена исправлена от руки (было 1 600) | I12: Потолки и монтаж
B13: 5 | C13: Монтаж скрытых плинтусов (полная работа от и до) | D13: м.п. | E13: 1500 | G13: =IF(OR(F13="",F13=0),0,E13*F13) | I13: Потолки и монтаж
B14: 6 | C14: Монтаж трековых светильников | D14: м.п. | E14: 2000 | G14: =IF(OR(F14="",F14=0),0,E14*F14) | I14: Потолки и монтаж
B15: 7 | C15: Монтаж откосов сэндвич-панелями 45° | D15: м.п. | E15: 1500 | G15: =IF(OR(F15="",F15=0),0,E15*F15) | I15: Потолки и монтаж
B16: 8 | C16: Монтаж проёмов (скрытые двери), полная работа от и до | D16: м.п. | E16: 1200 | G16: =IF(OR(F16="",F16=0),0,E16*F16) | I16: Потолки и монтаж
B17: 9 | C17: Монтаж оконных подоконников | D17: м.п. | E17: 1200 | G17: =IF(OR(F17="",F17=0),0,E17*F17) | I17: Потолки и монтаж
B18: 10 | C18: Поклейка бумажной лентой | D18: м.п. | E18: 300 | G18: =IF(OR(F18="",F18=0),0,E18*F18) | I18: Потолки и монтаж
B19: 11 | C19: Монтаж потолка Армстронг | D19: м² | E19: 500 | G19: =IF(OR(F19="",F19=0),0,E19*F19) | I19: Потолки и монтаж
B20: Грунтование
B21: 13 | C21: Грунтовка | D21: м² | E21: 100 | G21: =IF(OR(F21="",F21=0),0,E21*F21) | H21: Цена вписана от руки | I21: Грунтование
B22: 14 | C22: Грунтовка бетоноконтактом | D22: м² | E22: 120 | G22: =IF(OR(F22="",F22=0),0,E22*F22) | I22: Грунтование
B23: Гипсокартон и утепление
B24: 15 | C24: Устройство ГКЛ-потолка 1-уровневого (1 слой) | D24: м² | E24: 1600 | G24: =IF(OR(F24="",F24=0),0,E24*F24) | I24: Гипсокартон и утепление
B25: 16 | C25: Устройство двойного каркаса в потолок (в 1 слой ГКЛ) | D25: м² | E25: 2000 | G25: =IF(OR(F25="",F25=0),0,E25*F25) | I25: Гипсокартон и утепление
B26: 17 | C26: Устройство двойного каркаса в потолок (в 2 слоя ГКЛ) | D26: м² | E26: 2500 | G26: =IF(OR(F26="",F26=0),0,E26*F26) | I26: Гипсокартон и утепление
B27: 18 | C27: Устройство ГКЛ-потолка 1-уровневого (2 слоя) | D27: м² | E27: 2000 | G27: =IF(OR(F27="",F27=0),0,E27*F27) | I27: Гипсокартон и утепление
B28: 19 | C28: Обшивка стен ГКЛ по металлическому каркасу (в 1 слой) | D28: м² | E28: 1500 | G28: =IF(OR(F28="",F28=0),0,E28*F28) | I28: Гипсокартон и утепление
B29: 20 | C29: Обшивка стен ГКЛ по металлическому каркасу (в 2 слоя) | D29: м² | E29: 2000 | G29: =IF(OR(F29="",F29=0),0,E29*F29) | I29: Гипсокартон и утепление
B30: 21 | C30: Обшивка откосов ГКЛ в 1 слой | D30: м.п. | E30: 1000 | G30: =IF(OR(F30="",F30=0),0,E30*F30) | I30: Гипсокартон и утепление
B31: 22 | C31: Устройство ГКЛ-перегородок (в 1 слой) | D31: м² | E31: 1500 | G31: =IF(OR(F31="",F31=0),0,E31*F31) | I31: Гипсокартон и утепление
B32: 23 | C32: Устройство ГКЛ-перегородок (в 2 слоя) | D32: м² | E32: 2000 | G32: =IF(OR(F32="",F32=0),0,E32*F32) | I32: Гипсокартон и утепление
B33: 24 | C33: Утепление стен и перегородок (минвата / ЭППС / пенопласт) | D33: м² | E33: 200 | G33: =IF(OR(F33="",F33=0),0,E33*F33) | I33: Гипсокартон и утепление
B34: Штукатурка и шпатлёвка
B35: 25 | C35: Оштукатуривание стен (по маякам) до 30 мм | D35: м² | E35: 600 | G35: =IF(OR(F35="",F35=0),0,E35*F35) | H35: Цена исправлена от руки | I35: Штукатурка и шпатлёвка
B36: 26 | C36: Выравнивание стен шлифмашинкой | D36: м² | E36: 200 | G36: =IF(OR(F36="",F36=0),0,E36*F36) | I36: Штукатурка и шпатлёвка
B37: 27 | C37: Оштукатуривание откосов (под маяк) | D37: м² | E37: 500 | G37: =IF(OR(F37="",F37=0),0,E37*F37) | I37: Штукатурка и шпатлёвка
B38: 28 | C38: Оштукатуривание фасадной сеткой (в один слой) | D38: м² | E38: 600 | G38: =IF(OR(F38="",F38=0),0,E38*F38) | H38: Цена исправлена от руки | I38: Штукатурка и шпатлёвка
B39: 29 | C39: Оштукатуривание фасадной сеткой (в два слоя) | D39: м² | E39: 1600 | G39: =IF(OR(F39="",F39=0),0,E39*F39) | H39: Цена исправлена от руки | I39: Штукатурка и шпатлёвка
B40: 30 | C40: Выравнивание стен (под правило) до 10 мм | D40: м² | E40: 500 | G40: =IF(OR(F40="",F40=0),0,E40*F40) | I40: Штукатурка и шпатлёвка
B41: 31 | C41: Шпатлёвка потолков под покраску за 2 раза (включая шлифовку) | D41: м² | E41: 1000 | G41: =IF(OR(F41="",F41=0),0,E41*F41) | H41: Цена исправлена от руки | I41: Штукатурка и шпатлёвка
B42: 31а | C42: Монтаж цоколя с пенопластом | D42: м² | E42: 900 | G42: =IF(OR(F42="",F42=0),0,E42*F42) | H42: Добавлено от руки внизу 1-й страницы | I42: Штукатурка и шпатлёвка
...

Sheet Смета
B2: СМЕТА
B3: Объект | E3: Дата | G3: Заказчик
E4: =TODAY()
B6: Сюда попадают только позиции, у которых на листе «Расценки» заполнено количество. Меняйте объёмы там — смета обновится сама.
B7: № | C7: Наименование работ | D7: Ед. изм. | E7: Цена, ₽ | F7: Кол-во | G7: Сумма, ₽ | H7: Раздел
A8: =IFERROR(AGGREGATE(15,6,ROW(Расценки!$F$7:$F$76)/(Расценки!$F$7:$F$76>0),1),"") | B8: =IF($A8="","",INDEX(Расценки!B:B,$A8)) | C8: =IF($A8="","",INDEX(Расценки!C:C,$A8)) | D8: =IF($A8="","",INDEX(Расценки!D:D,$A8)) | E8: =IF($A8="","",INDEX(Расценки!E:E,$A8)) | F8: =IF($A8="","",INDEX(Расценки!F:F,$A8)) | G8: =IF($A8="","",INDEX(Расценки!G:G,$A8)) | H8: =IF($A8="","",INDEX(Расценки!I:I,$A8))
A9: =IFERROR(AGGREGATE(15,6,ROW(Расценки!$F$7:$F$76)/(Расценки!$F$7:$F$76>0),2),"") | B9: =IF($A9="","",INDEX(Расценки!B:B,$A9)) | C9: =IF($A9="","",INDEX(Расценки!C:C,$A9)) | D9: =IF($A9="","",INDEX(Расценки!D:D,$A9)) | E9: =IF($A9="","",INDEX(Расценки!E:E,$A9)) | F9: =IF($A9="","",INDEX(Расценки!F:F,$A9)) | G9: =IF($A9="","",INDEX(Расценки!G:G,$A9)) | H9: =IF($A9="","",INDEX(Расценки!I:I,$A9))
A10: =IFERROR(AGGREGATE(15,6,ROW(Расценки!$F$7:$F$76)/(Расценки!$F$7:$F$76>0),3),"") | B10: =IF($A10="","",INDEX(Расценки!B:B,$A10)) | C10: =IF($A10="","",INDEX(Расценки!C:C,$A10)) | D10: =IF($A10="","",INDEX(Расценки!D:D,$A10)) | E10: =IF($A10="","",INDEX(Расценки!E:E,$A10)) | F10: =IF($A10="","",INDEX(Расценки!F:F,$A10)) | G10: =IF($A10="","",INDEX(Расценки!G:G,$A10)) | H10: =IF($A10="","",INDEX(Расценки!I:I,$A10))
A11: =IFERROR(AGGREGATE(15,6,ROW(Расценки!$F$7:$F$76)/(Расценки!$F$7:$F$76>0),4),"") | B11: =IF($A11="","",INDEX(Расценки!B:B,$A11)) | C11: =IF($A11="","",INDEX(Расценки!C:C,$A11)) | D11: =IF($A11="","",INDEX(Расценки!D:D,$A11)) | E11: =IF($A11="","",INDEX(Расценки!E:E,$A11)) | F11: =IF($A11="","",INDEX(Расценки!F:F,$A11)) | G11: =IF($A11="","",INDEX(Расценки!G:G,$A11)) | H11: =IF($A11="","",INDEX(Расценки!I:I,$A11))
A12: =IFERROR(AGGREGATE(15,6,ROW(Расценки!$F$7:$F$76)/(Расценки!$F$7:$F$76>0),5),"") | B12: =IF($A12="","",INDEX(Расценки!B:B,$A12)) | C12: =IF($A12="","",INDEX(Расценки!C:C,$A12)) | D12: =IF($A12="","",INDEX(Расценки!D:D,$A12)) | E12: =IF($A12="","",INDEX(Расценки!E:E,$A12)) | F12: =IF($A12="","",INDEX(Расценки!F:F,$A12)) | G12: =IF($A12="","",INDEX(Расценки!G:G,$A12)) | H12: =IF($A12="","",INDEX(Расценки!I:I,$A12))
A13: =IFERROR(AGGREGATE(15,6,ROW(Расценки!$F$7:$F$76)/(Расценки!$F$7:$F$76>0),6),"") | B13: =IF($A13="","",INDEX(Расценки!B:B,$A13)) | C13: =IF($A13="","",INDEX(Расценки!C:C,$A13)) | D13: =IF($A13="","",INDEX(Расценки!D:D,$A13)) | E13: =IF($A13="","",INDEX(Расценки!E:E,$A13)) | F13: =IF($A13="","",INDEX(Расценки!F:F,$A13)) | G13: =IF($A13="","",INDEX(Расценки!G:G,$A13)) | H13: =IF($A13="","",INDEX(Расценки!I:I,$A13))
A14: =IFERROR(AGGREGATE(15,6,ROW(Расценки!$F$7:$F$76)/(Расценки!$F$7:$F$76>0),7),"") | B14: =IF($A14="","",INDEX(Расценки!B:B,$A14)) | C14: =IF($A14="","",INDEX(Расценки!C:C,$A14)) | D14: =IF($A14="","",INDEX(Расценки!D:D,$A14)) | E14: =IF($A14="","",INDEX(Расценки!E:E,$A14)) | F14: =IF($A14="","",INDEX(Расценки!F:F,$A14)) | G14: =IF($A14="","",INDEX(Расценки!G:G,$A14)) | H14: =IF($A14="","",INDEX(Расценки!I:I,$A14))
A15: =IFERROR(AGGREGATE(15,6,ROW(Расценки!$F$7:$F$76)/(Расценки!$F$7:$F$76>0),8),"") | B15: =IF($A15="","",INDEX(Расценки!B:B,$A15)) | C15: =IF($A15="","",INDEX(Расценки!C:C,$A15)) | D15: =IF($A15="","",INDEX(Расценки!D:D,$A15)) | E15: =IF($A15="","",INDEX(Расценки!E:E,$A15)) | F15: =IF($A15="","",INDEX(Расценки!F:F,$A15)) | G15: =IF($A15="","",INDEX(Расценки!G:G,$A15)) | H15: =IF($A15="","",INDEX(Расценки!I:I,$A15))
A16: =IFERROR(AGGREGATE(15,6,ROW(Расценки!$F$7:$F$76)/(Расценки!$F$7:$F$76>0),9),"") | B16: =IF($A16="","",INDEX(Расценки!B:B,$A16)) | C16: =IF($A16="","",INDEX(Расценки!C:C,$A16)) | D16: =IF($A16="","",INDEX(Расценки!D:D,$A16)) | E16: =IF($A16="","",INDEX(Расценки!E:E,$A16)) | F16: =IF($A16="","",INDEX(Расценки!F:F,$A16)) | G16: =IF($A16="","",INDEX(Расценки!G:G,$A16)) | H16: =IF($A16="","",INDEX(Расценки!I:I,$A16))
A17: =IFERROR(AGGREGATE(15,6,ROW(Расценки!$F$7:$F$76)/(Расценки!$F$7:$F$76>0),10),"") | B17: =IF($A17="","",INDEX(Расценки!B:B,$A17)) | C17: =IF($A17="","",INDEX(Расценки!C:C,$A17)) | D17: =IF($A17="","",INDEX(Расценки!D:D,$A17)) | E17: =IF($A17="","",INDEX(Расценки!E:E,$A17)) | F17: =IF($A17="","",INDEX(Расценки!F:F,$A17)) | G17: =IF($A17="","",INDEX(Расценки!G:G,$A17)) | H17: =IF($A17="","",INDEX(Расценки!I:I,$A17))
A18: =IFERROR(AGGREGATE(15,6,ROW(Расценки!$F$7:$F$76)/(Расценки!$F$7:$F$76>0),11),"") | B18: =IF($A18="","",INDEX(Расценки!B:B,$A18)) | C18: =IF($A18="","",INDEX(Расценки!C:C,$A18)) | D18: =IF($A18="","",INDEX(Расценки!D:D,$A18)) | E18: =IF($A18="","",INDEX(Расценки!E:E,$A18)) | F18: =IF($A18="","",INDEX(Расценки!F:F,$A18)) | G18: =IF($A18="","",INDEX(Расценки!G:G,$A18)) | H18: =IF($A18="","",INDEX(Расценки!I:I,$A18))
A19: =IFERROR(AGGREGATE(15,6,ROW(Расценки!$F$7:$F$76)/(Расценки!$F$7:$F$76>0),12),"") | B19: =IF($A19="","",INDEX(Расценки!B:B,$A19)) | C19: =IF($A19="","",INDEX(Расценки!C:C,$A19)) | D19: =IF($A19="","",INDEX(Расценки!D:D,$A19)) | E19: =IF($A19="","",INDEX(Расценки!E:E,$A19)) | F19: =IF($A19="","",INDEX(Расценки!F:F,$A19)) | G19: =IF($A19="","",INDEX(Расценки!G:G,$A19)) | H19: =IF($A19="","",INDEX(Расценки!I:I,$A19))
A20: =IFERROR(AGGREGATE(15,6,ROW(Расценки!$F$7:$F$76)/(Расценки!$F$7:$F$76>0),13),"") | B20: =IF($A20="","",INDEX(Расценки!B:B,$A20)) | C20: =IF($A20="","",INDEX(Расценки!C:C,$A20)) | D20: =IF($A20="","",INDEX(Расценки!D:D,$A20)) | E20: =IF($A20="","",INDEX(Расценки!E:E,$A20)) | F20: =IF($A20="","",INDEX(Расценки!F:F,$A20)) | G20: =IF($A20="","",INDEX(Расценки!G:G,$A20)) | H20: =IF($A20="","",INDEX(Расценки!I:I,$A20))
A21: =IFERROR(AGGREGATE(15,6,ROW(Расценки!$F$7:$F$76)/(Расценки!$F$7:$F$76>0),14),"") | B21: =IF($A21="","",INDEX(Расценки!B:B,$A21)) | C21: =IF($A21="","",INDEX(Расценки!C:C,$A21)) | D21: =IF($A21="","",INDEX(Расценки!D:D,$A21)) | E21: =IF($A21="","",INDEX(Расценки!E:E,$A21)) | F21: =IF($A21="","",INDEX(Расценки!F:F,$A21)) | G21: =IF($A21="","",INDEX(Расценки!G:G,$A21)) | H21: =IF($A21="","",INDEX(Расценки!I:I,$A21))
A22: =IFERROR(AGGREGATE(15,6,ROW(Расценки!$F$7:$F$76)/(Расценки!$F$7:$F$76>0),15),"") | B22: =IF($A22="","",INDEX(Расценки!B:B,$A22)) | C22: =IF($A22="","",INDEX(Расценки!C:C,$A22)) | D22: =IF($A22="","",INDEX(Расценки!D:D,$A22)) | E22: =IF($A22="","",INDEX(Расценки!E:E,$A22)) | F22: =IF($A22="","",INDEX(Расценки!F:F,$A22)) | G22: =IF($A22="","",INDEX(Расценки!G:G,$A22)) | H22: =IF($A22="","",INDEX(Расценки!I:I,$A22))
A23: =IFERROR(AGGREGATE(15,6,ROW(Расценки!$F$7:$F$76)/(Расценки!$F$7:$F$76>0),16),"") | B23: =IF($A23="","",INDEX(Расценки!B:B,$A23)) | C23: =IF($A23="","",INDEX(Расценки!C:C,$A23)) | D23: =IF($A23="","",INDEX(Расценки!D:D,$A23)) | E23: =IF($A23="","",INDEX(Расценки!E:E,$A23)) | F23: =IF($A23="","",INDEX(Расценки!F:F,$A23)) | G23: =IF($A23="","",INDEX(Расценки!G:G,$A23)) | H23: =IF($A23="","",INDEX(Расценки!I:I,$A23))
A24: =IFERROR(AGGREGATE(15,6,ROW(Расценки!$F$7:$F$76)/(Расценки!$F$7:$F$76>0),17),"") | B24: =IF($A24="","",INDEX(Расценки!B:B,$A24)) | C24: =IF($A24="","",INDEX(Расценки!C:C,$A24)) | D24: =IF($A24="","",INDEX(Расценки!D:D,$A24)) | E24: =IF($A24="","",INDEX(Расценки!E:E,$A24)) | F24: =IF($A24="","",INDEX(Расценки!F:F,$A24)) | G24: =IF($A24="","",INDEX(Расценки!G:G,$A24)) | H24: =IF($A24="","",INDEX(Расценки!I:I,$A24))
A25: =IFERROR(AGGREGATE(15,6,ROW(Расценки!$F$7:$F$76)/(Расценки!$F$7:$F$76>0),18),"") | B25: =IF($A25="","",INDEX(Расценки!B:B,$A25)) | C25: =IF($A25="","",INDEX(Расценки!C:C,$A25)) | D25: =IF($A25="","",INDEX(Расценки!D:D,$A25)) | E25: =IF($A25="","",INDEX(Расценки!E:E,$A25)) | F25: =IF($A25="","",INDEX(Расценки!F:F,$A25)) | G25: =IF($A25="","",INDEX(Расценки!G:G,$A25)) | H25: =IF($A25="","",INDEX(Расценки!I:I,$A25))
A26: =IFERROR(AGGREGATE(15,6,ROW(Расценки!$F$7:$F$76)/(Расценки!$F$7:$F$76>0),19),"") | B26: =IF($A26="","",INDEX(Расценки!B:B,$A26)) | C26: =IF($A26="","",INDEX(Расценки!C:C,$A26)) | D26: =IF($A26="","",INDEX(Расценки!D:D,$A26)) | E26: =IF($A26="","",INDEX(Расценки!E:E,$A26)) | F26: =IF($A26="","",INDEX(Расценки!F:F,$A26)) | G26: =IF($A26="","",INDEX(Расценки!G:G,$A26)) | H26: =IF($A26="","",INDEX(Расценки!I:I,$A26))
A27: =IFERROR(AGGREGATE(15,6,ROW(Расценки!$F$7:$F$76)/(Расценки!$F$7:$F$76>0),20),"") | B27: =IF($A27="","",INDEX(Расценки!B:B,$A27)) | C27: =IF($A27="","",INDEX(Расценки!C:C,$A27)) | D27: =IF($A27="","",INDEX(Расценки!D:D,$A27)) | E27: =IF($A27="","",INDEX(Расценки!E:E,$A27)) | F27: =IF($A27="","",INDEX(Расценки!F:F,$A27)) | G27: =IF($A27="","",INDEX(Расценки!G:G,$A27)) | H27: =IF($A27="","",INDEX(Расценки!I:I,$A27))
A28: =IFERROR(AGGREGATE(15,6,ROW(Расценки!$F$7:$F$76)/(Расценки!$F$7:$F$76>0),21),"") | B28: =IF($A28="","",INDEX(Расценки!B:B,$A28)) | C28: =IF($A28="","",INDEX(Расценки!C:C,$A28)) | D28: =IF($A28="","",INDEX(Расценки!D:D,$A28)) | E28: =IF($A28="","",INDEX(Расценки!E:E,$A28)) | F28: =IF($A28="","",INDEX(Расценки!F:F,$A28)) | G28: =IF($A28="","",INDEX(Расценки!G:G,$A28)) | H28: =IF($A28="","",INDEX(Расценки!I:I,$A28))
A29: =IFERROR(AGGREGATE(15,6,ROW(Расценки!$F$7:$F$76)/(Расценки!$F$7:$F$76>0),22),"") | B29: =IF($A29="","",INDEX(Расценки!B:B,$A29)) | C29: =IF($A29="","",INDEX(Расценки!C:C,$A29)) | D29: =IF($A29="","",INDEX(Расценки!D:D,$A29)) | E29: =IF($A29="","",INDEX(Расценки!E:E,$A29)) | F29: =IF($A29="","",INDEX(Расценки!F:F,$A29)) | G29: =IF($A29="","",INDEX(Расценки!G:G,$A29)) | H29: =IF($A29="","",INDEX(Расценки!I:I,$A29))
A30: =IFERROR(AGGREGATE(15,6,ROW(Расценки!$F$7:$F$76)/(Расценки!$F$7:$F$76>0),23),"") | B30: =IF($A30="","",INDEX(Расценки!B:B,$A30)) | C30: =IF($A30="","",INDEX(Расценки!C:C,$A30)) | D30: =IF($A30="","",INDEX(Расценки!D:D,$A30)) | E30: =IF($A30="","",INDEX(Расценки!E:E,$A30)) | F30: =IF($A30="","",INDEX(Расценки!F:F,$A30)) | G30: =IF($A30="","",INDEX(Расценки!G:G,$A30)) | H30: =IF($A30="","",INDEX(Расценки!I:I,$A30))
A31: =IFERROR(AGGREGATE(15,6,ROW(Расценки!$F$7:$F$76)/(Расценки!$F$7:$F$76>0),24),"") | B31: =IF($A31="","",INDEX(Расценки!B:B,$A31)) | C31: =IF($A31="","",INDEX(Расценки!C:C,$A31)) | D31: =IF($A31="","",INDEX(Расценки!D:D,$A31)) | E31: =IF($A31="","",INDEX(Расценки!E:E,$A31)) | F31: =IF($A31="","",INDEX(Расценки!F:F,$A31)) | G31: =IF($A31="","",INDEX(Расценки!G:G,$A31)) | H31: =IF($A31="","",INDEX(Расценки!I:I,$A31))
A32: =IFERROR(AGGREGATE(15,6,ROW(Расценки!$F$7:$F$76)/(Расценки!$F$7:$F$76>0),25),"") | B32: =IF($A32="","",INDEX(Расценки!B:B,$A32)) | C32: =IF($A32="","",INDEX(Расценки!C:C,$A32)) | D32: =IF($A32="","",INDEX(Расценки!D:D,$A32)) | E32: =IF($A32="","",INDEX(Расценки!E:E,$A32)) | F32: =IF($A32="","",INDEX(Расценки!F:F,$A32)) | G32: =IF($A32="","",INDEX(Расценки!G:G,$A32)) | H32: =IF($A32="","",INDEX(Расценки!I:I,$A32))
A33: =IFERROR(AGGREGATE(15,6,ROW(Расценки!$F$7:$F$76)/(Расценки!$F$7:$F$76>0),26),"") | B33: =IF($A33="","",INDEX(Расценки!B:B,$A33)) | C33: =IF($A33="","",INDEX(Расценки!C:C,$A33)) | D33: =IF($A33="","",INDEX(Расценки!D:D,$A33)) | E33: =IF($A33="","",INDEX(Расценки!E:E,$A33)) | F33: =IF($A33="","",INDEX(Расценки!F:F,$A33)) | G33: =IF($A33="","",INDEX(Расценки!G:G,$A33)) | H33: =IF($A33="","",INDEX(Расценки!I:I,$A33))
A34: =IFERROR(AGGREGATE(15,6,ROW(Расценки!$F$7:$F$76)/(Расценки!$F$7:$F$76>0),27),"") | B34: =IF($A34="","",INDEX(Расценки!B:B,$A34)) | C34: =IF($A34="","",INDEX(Расценки!C:C,$A34)) | D34: =IF($A34="","",INDEX(Расценки!D:D,$A34)) | E34: =IF($A34="","",INDEX(Расценки!E:E,$A34)) | F34: =IF($A34="","",INDEX(Расценки!F:F,$A34)) | G34: =IF($A34="","",INDEX(Расценки!G:G,$A34)) | H34: =IF($A34="","",INDEX(Расценки!I:I,$A34))
A35: =IFERROR(AGGREGATE(15,6,ROW(Расценки!$F$7:$F$76)/(Расценки!$F$7:$F$76>0),28),"") | B35: =IF($A35="","",INDEX(Расценки!B:B,$A35)) | C35: =IF($A35="","",INDEX(Расценки!C:C,$A35)) | D35: =IF($A35="","",INDEX(Расценки!D:D,$A35)) | E35: =IF($A35="","",INDEX(Расценки!E:E,$A35)) | F35: =IF($A35="","",INDEX(Расценки!F:F,$A35)) | G35: =IF($A35="","",INDEX(Расценки!G:G,$A35)) | H35: =IF($A35="","",INDEX(Расценки!I:I,$A35))
A36: =IFERROR(AGGREGATE(15,6,ROW(Расценки!$F$7:$F$76)/(Расценки!$F$7:$F$76>0),29),"") | B36: =IF($A36="","",INDEX(Расценки!B:B,$A36)) | C36: =IF($A36="","",INDEX(Расценки!C:C,$A36)) | D36: =IF($A36="","",INDEX(Расценки!D:D,$A36)) | E36: =IF($A36="","",INDEX(Расценки!E:E,$A36)) | F36: =IF($A36="","",INDEX(Расценки!F:F,$A36)) | G36: =IF($A36="","",INDEX(Расценки!G:G,$A36)) | H36: =IF($A36="","",INDEX(Расценки!I:I,$A36))
A37: =IFERROR(AGGREGATE(15,6,ROW(Расценки!$F$7:$F$76)/(Расценки!$F$7:$F$76>0),30),"") | B37: =IF($A37="","",INDEX(Расценки!B:B,$A37)) | C37: =IF($A37="","",INDEX(Расценки!C:C,$A37)) | D37: =IF($A37="","",INDEX(Расценки!D:D,$A37)) | E37: =IF($A37="","",INDEX(Расценки!E:E,$A37)) | F37: =IF($A37="","",INDEX(Расценки!F:F,$A37)) | G37: =IF($A37="","",INDEX(Расценки!G:G,$A37)) | H37: =IF($A37="","",INDEX(Расценки!I:I,$A37))
A38: =IFERROR(AGGREGATE(15,6,ROW(Расценки!$F$7:$F$76)/(Расценки!$F$7:$F$76>0),31),"") | B38: =IF($A38="","",INDEX(Расценки!B:B,$A38)) | C38: =IF($A38="","",INDEX(Расценки!C:C,$A38)) | D38: =IF($A38="","",INDEX(Расценки!D:D,$A38)) | E38: =IF($A38="","",INDEX(Расценки!E:E,$A38)) | F38: =IF($A38="","",INDEX(Расценки!F:F,$A38)) | G38: =IF($A38="","",INDEX(Расценки!G:G,$A38)) | H38: =IF($A38="","",INDEX(Расценки!I:I,$A38))
A39: =IFERROR(AGGREGATE(15,6,ROW(Расценки!$F$7:$F$76)/(Расценки!$F$7:$F$76>0),32),"") | B39: =IF($A39="","",INDEX(Расценки!B:B,$A39)) | C39: =IF($A39="","",INDEX(Расценки!C:C,$A39)) | D39: =IF($A39="","",INDEX(Расценки!D:D,$A39)) | E39: =IF($A39="","",INDEX(Расценки!E:E,$A39)) | F39: =IF($A39="","",INDEX(Расценки!F:F,$A39)) | G39: =IF($A39="","",INDEX(Расценки!G:G,$A39)) | H39: =IF($A39="","",INDEX(Расценки!I:I,$A39))
A40: =IFERROR(AGGREGATE(15,6,ROW(Расценки!$F$7:$F$76)/(Расценки!$F$7:$F$76>0),33),"") | B40: =IF($A40="","",INDEX(Расценки!B:B,$A40)) | C40: =IF($A40="","",INDEX(Расценки!C:C,$A40)) | D40: =IF($A40="","",INDEX(Расценки!D:D,$A40)) | E40: =IF($A40="","",INDEX(Расценки!E:E,$A40)) | F40: =IF($A40="","",INDEX(Расценки!F:F,$A40)) | G40: =IF($A40="","",INDEX(Расценки!G:G,$A40)) | H40: =IF($A40="","",INDEX(Расценки!I:I,$A40))
A41: =IFERROR(AGGREGATE(15,6,ROW(Расценки!$F$7:$F$76)/(Расценки!$F$7:$F$76>0),34),"") | B41: =IF($A41="","",INDEX(Расценки!B:B,$A41)) | C41: =IF($A41="","",INDEX(Расценки!C:C,$A41)) | D41: =IF($A41="","",INDEX(Расценки!D:D,$A41)) | E41: =IF($A41="","",INDEX(Расценки!E:E,$A41)) | F41: =IF($A41="","",INDEX(Расценки!F:F,$A41)) | G41: =IF($A41="","",INDEX(Расценки!G:G,$A41)) | H41: =IF($A41="","",INDEX(Расценки!I:I,$A41))
A42: =IFERROR(AGGREGATE(15,6,ROW(Расценки!$F$7:$F$76)/(Расценки!$F$7:$F$76>0),35),"") | B42: =IF($A42="","",INDEX(Расценки!B:B,$A42)) | C42: =IF($A42="","",INDEX(Расценки!C:C,$A42)) | D42: =IF($A42="","",INDEX(Расценки!D:D,$A42)) | E42: =IF($A42="","",INDEX(Расценки!E:E,$A42)) | F42: =IF($A42="","",INDEX(Расценки!F:F,$A42)) | G42: =IF($A42="","",INDEX(Расценки!G:G,$A42)) | H42: =IF($A42="","",INDEX(Расценки!I:I,$A42))
...

Sheet О скане
B2: Как собран этот файл
B3: Источник — двухстраничный скан «Расценки, сентябрь». Текст набран заново, цены сверены.
B5: Структура | C5: Сохранены исходные номера позиций. В скане нет № 12. Доборы в скане повторно помечены как № 57 — здесь это 58а.
B6: Рукописные правки | C6: Жёлтые строки: цена зачёркнута и вписана от руки, либо позиция дописана внизу первой страницы (цоколь, фасадный декор).
B7: Обведённые позиции | C7: Розовые строки 43–45 (плитка: облицовка стен, лючок, эпоксидная затирка) обведены на скане.
B8: Не входит | C8: Сверление отверстий в плитке (№ 48) зачёркнуто и подписано «не входит». Цена сохранена для справки, в итог попадёт только если указать количество.
B9: Позиция № 34 | C9: Шпатлёвка стен под покраску: в скане 800 ₽ и знак «?». Имеет смысл перепроверить.
B10: Единицы | C10: м² — квадратный метр, м.п. — метр погонный, шт. — штука.
B11: Смета | C11: На листе «Расценки» введите объёмы в зелёные ячейки «Кол-во». Итог и лист «Смета» пересчитаются автоматически.
B12: Нумерация дверей | C12: 56 — входные металлические, 57 — межкомнатные, 58 — двухстворчатая, 58а — доборы, 59 — врезка замков, 60 — наличник.
B14: Условные обозначения заливки
B15: Жёлтый | C15: Исправлено или добавлено от руки
B16: Розовый | C16: Обведено на скане
B17: Серый | C17: Помечено «не входит»
B18: Зелёный | C18: Поле для ввода количества
